Workbook

Sheet Start here
B2: SnailPulse — KiCad schematic connection workbook
B3: Orbita 2026 · everything you need to draw the schematic, part by part
B5: How to use this workbook
B6: 1. Parts tab — place every symbol in KiCad (Add Symbol, A). Copy the Symbol name into the search box.
B7: 2. Wiring tab — go part by part, pin by pin. Draw what the 'Net' column says, then pick ✓ in the Done column. The row turns green.
B8: 3. Nets tab — cross-check: every net should have the pin count shown. 'Pins found' updates from the Wiring tab.
B9: 4. Connectors tab — which wire from each plug goes where off the board (cable colours too).
B10: 5. Run ERC (Inspect → Electrical Rules Checker) and fix everything before assigning footprints.
B12: Colour key — blocks (same blocks as the drawings in chat)
B13: A · Heartbeat amplifier
B14: B · 1.65 V reference
B15: C · Heater power switch
... B42: • R12 gate pull-down now goes to GNDPWR (right next to Q1's source) instead of signal GND.

Sheet Parts
A1: Block | B1: Ref | C1: Value | D1: What it does | E1: KiCad symbol (Add Symbol → search) | F1: Footprint | G1: On board? | H1: Placed
A2: A · Heartbeat amplifier
A3: A | B3: U3 | C3: TCRT5000 | D3: IR sensor on the snail shell (LED + phototransistor) | E3: Sensor_Proximity:TCRT5000 (if missing: Sensor_Proximity:CNY70, same pin names) | F3: — (off-board, tick “Exclude from board”) | G3: No — off-board
A4: A | B4: J1 | C4: Conn 1×4 (JST-XH) | D4: Plug for the sensor cable | E4: Connector_Generic:Conn_01x04 | F4: Connector_JST:JST_XH_B4B-XH-A_1x04_P2.50mm_Vertical | G4: Yes
A5: A | B5: R1 | C5: 220Ω | D5: Sets IR LED current (~17 mA) | E5: Device:R | F5: Resistor_THT:R_Axial_DIN0207_L6.3mm_D2.5mm_P7.62mm_Horizontal | G5: Yes
A6: A | B6: RV1 | C6: 50k trim | D6: Phototransistor load — turns light into voltage | E6: Device:R_Potentiometer_Trim | F6: Potentiometer_THT:Potentiometer_Bourns_3296W_Vertical | G6: Yes
A7: A | B7: C1 | C7: 1µF | D7: High-pass: blocks the steady DC level | E7: Device:C | F7: Capacitor_THT:C_Disc_D5.0mm_W2.5mm_P5.00mm | G7: Yes
A8: A | B8: R2 | C8: 1M | D8: High-pass: re-centres signal on 1.65 V | E8: Device:R | F8: Resistor_THT:R_Axial_DIN0207_L6.3mm_D2.5mm_P7.62mm_Horizontal | G8: Yes
A9: A | B9: U1 | C9: MCP6002 · unit A | D9: Amplifier, gain 101 | E9: Amplifier_Operational:MCP6002-xP (unit A) | F9: Package_DIP:DIP-8_W7.62mm_Socket | G9: Yes
A10: A | B10: R3 | C10: 1k | D10: Gain resistor (to VREF) | E10: Device:R | F10: Resistor_THT:R_Axial_DIN0207_L6.3mm_D2.5mm_P7.62mm_Horizontal | G10: Yes
A11: A | B11: R4 | C11: 100k | D11: Feedback resistor | E11: Device:R | F11: Resistor_THT:R_Axial_DIN0207_L6.3mm_D2.5mm_P7.62mm_Horizontal | G11: Yes
A12: A | B12: C2 | C12: 470nF | D12: Low-pass ~3.4 Hz (across R4) | E12: Device:C | F12: Capacitor_THT:C_Disc_D5.0mm_W2.5mm_P5.00mm | G12: Yes
A13: A | B13: R5 | C13: 1k | D13: ADC input filter + pin protection | E13: Device:R | F13: Resistor_THT:R_Axial_DIN0207_L6.3mm_D2.5mm_P7.62mm_Horizontal | G13: Yes
A14: A | B14: C3 | C14: 100nF | D14: ADC input filter | E14: Device:C | F14: Capacitor_THT:C_Disc_D5.0mm_W2.5mm_P5.00mm | G14: Yes
A15: B · 1.65 V reference
A16: B | B16: R6 | C16: 10k | D16: Divider top (3.3 V → 1.65 V) | E16: Device:R | F16: Resistor_THT:R_Axial_DIN0207_L6.3mm_D2.5mm_P7.62mm_Horizontal | G16: Yes
A17: B | B17: R7 | C17: 10k | D17: Divider bottom | E17: Device:R | F17: Resistor_THT:R_Axial_DIN0207_L6.3mm_D2.5mm_P7.62mm_Horizontal | G17: Yes
A18: B | B18: C4 | C18: 10µF | D18: Smooths the divider | E18: Device:C_Polarized | F18: Capacitor_THT:CP_Radial_D5.0mm_P2.00mm | G18: Yes
A19: B | B19: U1 | C19: MCP6002 · unit B | D19: Buffer → makes VREF | E19: Amplifier_Operational:MCP6002-xP (unit B) | F19: Package_DIP:DIP-8_W7.62mm_Socket | G19: Yes
A20: B | B20: U1 | C20: MCP6002 · unit C (power) | D20: Power pins of U1 | E20: Amplifier_Operational:MCP6002-xP (unit C) | F20: Package_DIP:DIP-8_W7.62mm_Socket | G20: Yes
A21: B | B21: C5 | C21: 100nF | D21: Decoupling for U1 — place at pins 8–4 | E21: Device:C | F21: Capacitor_THT:C_Disc_D5.0mm_W2.5mm_P5.00mm | G21: Yes
A22: C · Heater power switch
A23: C | B23: J4 | C23: XT30 | D23: 14.8 V input from port X8 | E23: Connector_Generic:Conn_01x02 | F23: Connector_AMASS:AMASS_XT30U-M_1x02_P5.0mm_Vertical | G23: Yes
A24: C | B24: C6 | C24: 10µF 50V | D24: Absorbs PWM current pulses | E24: Device:C_Polarized | F24: Capacitor_THT:CP_Radial_D5.0mm_P2.00mm | G24: Yes
A25: C | B25: J5 | C25: Terminal 1×2 (KF2EDG) | D25: Heater wires out | E25: Connector_Generic:Conn_01x02 | F25: TerminalBlock:TerminalBlock_bornier-2_P5.08mm | G25: Yes
A26: C | B26: R8 | C26: 150Ω 5W | D26: Heater element (3 in parallel = 50 Ω) | E26: Device:R | F26: — (off-board, tick “Exclude from board”) | G26: No — off-board
A27: C | B27: R9 | C27: 150Ω 5W | D27: Heater element (3 in parallel = 50 Ω) | E27: Device:R | F27: — (off-board, tick “Exclude from board”) | G27: No — off-board
A28: C | B28: R10 | C28: 150Ω 5W | D28: Heater element (3 in parallel = 50 Ω) | E28: Device:R | F28: — (off-board, tick “Exclude from board”) | G28: No — off-board
A29: C | B29: Q1 | C29: IRLZ44N | D29: Switches heater on/off | E29: Transistor_FET:IRLZ44N | F29: Package_TO_SOT_THT:TO-220-3_Vertical | G29: Yes
A30: C | B30: R11 | C30: 1k | D30: Gate resistor — lets U2 overpower PC6 | E30: Device:R | F30: Resistor_THT:R_Axial_DIN0207_L6.3mm_D2.5mm_P7.62mm_Horizontal | G30: Yes
A31: C | B31: R12 | C31: 10k | D31: Gate pull-down — heater OFF during boot | E31: Device:R | F31: Resistor_THT:R_Axial_DIN0207_L6.3mm_D2.5mm_P7.62mm_Horizontal | G31: Yes
A32: C | B32: NT1 | C32: Net tie | D32: The ONE point where power ground meets signal ground | E32: Device:NetTie_2 | F32: NetTie:NetTie-2_THT_Pad1.0mm | G32: Yes
A33: D · Temperature + overheat cutoff
A34: D | B34: J6 | C34: Conn 1×4 (JST-XH) | D34: Plug for the two thermistors | E34: Connector_Generic:Conn_01x04 | F34: Connector_JST:JST_XH_B4B-XH-A_1x04_P2.50mm_Vertical | G34: Yes
A35: D | B35: TH1 | C35: NTC 10k | D35: Heater temp → firmware (PB1) | E35: Device:Thermistor_NTC | F35: — (off-board, tick “Exclude from board”) | G35: No — off-board
A36: D | B36: R14 | C36: 10k | D36: Divider with TH1 | E36: Device:R | F36: Resistor_THT:R_Axial_DIN0207_L6.3mm_D2.5mm_P7.62mm_Horizontal | G36: Yes
A37: D | B37: C10 | C37: 100nF | D37: Filters NTC1 reading | E37: Device:C | F37: Capacitor_THT:C_Disc_D5.0mm_W2.5mm_P5.00mm | G37: Yes
A38: D | B38: TH2 | C38: NTC 10k | D38: Heater temp → hardware cutoff | E38: Device:Thermistor_NTC | F38: — (off-board, tick “Exclude from board”) | G38: No — off-board
A39: D | B39: R13 | C39: 10k | D39: Divider with TH2 | E39: Device:R | F39: Resistor_THT:R_Axial_DIN0207_L6.3mm_D2.5mm_P7.62mm_Horizontal | G39: Yes
A40: D | B40: C11 | C40: 100nF | D40: Filters NTC2 (stops comparator chatter) | E40: Device:C | F40: Capacitor_THT:C_Disc_D5.0mm_W2.5mm_P5.00mm | G40: Yes
...

Sheet Wiring
A1: Pin-by-pin wiring — draw each row, then pick ✓
A2: ="Progress: "&COUNTIF(I5:I125,"✓")&" of 116 pins drawn" -> Progress: 0 of 116 pins drawn | E2: =COUNTIF(I5:I125,"✓")/116 -> 0
A4: Block | B4: Ref | C4: Part | D4: Pin # | E4: Pin name | F4: Net | G4: Connects to (other pins on this net) | H4: How to draw it in KiCad | I4: Done
A5: A · Heartbeat amplifier
A6: A | B6: U3 | C6: TCRT5000 | D6: A | E6: LED anode | F6: LED_A | G6: J1.1, R1.2 | H6: Wire (or label LED_A)
A7: A | B7: U3 | C7: TCRT5000 | D7: K | E7: LED cathode | F7: GND | G7: Power net — 27 pins share it (see Nets tab) | H7: power:GND symbol
A8: A | B8: U3 | C8: TCRT5000 | D8: C | E8: Collector | F8: +3V3 | G8: Power net — 13 pins share it (see Nets tab) | H8: power:+3V3 symbol
A9: A | B9: U3 | C9: TCRT5000 | D9: E | E9: Emitter | F9: SENSE | G9: J1.4, RV1.1, C1.1 | H9: Wire (or label SENSE)
A10: A | B10: J1 | C10: Conn 1×4 (JST-XH) | D10: 1 | E10: Pin_1 | F10: LED_A | G10: U3.A, R1.2 | H10: Wire (or label LED_A)
A11: A | B11: J1 | C11: Conn 1×4 (JST-XH) | D11: 2 | E11: Pin_2 | F11: GND | G11: Power net — 27 pins share it (see Nets tab) | H11: power:GND symbol
A12: A | B12: J1 | C12: Conn 1×4 (JST-XH) | D12: 3 | E12: Pin_3 | F12: +3V3 | G12: Power net — 13 pins share it (see Nets tab) | H12: power:+3V3 symbol
A13: A | B13: J1 | C13: Conn 1×4 (JST-XH) | D13: 4 | E13: Pin_4 | F13: SENSE | G13: U3.E, RV1.1, C1.1 | H13: Wire (or label SENSE)
A14: A | B14: R1 | C14: 220Ω | D14: 1 | E14: ~ | F14: +5V | G14: Power net — 4 pins share it (see Nets tab) | H14: power:+5V symbol
A15: A | B15: R1 | C15: 220Ω | D15: 2 | E15: ~ | F15: LED_A | G15: U3.A, J1.1 | H15: Wire (or label LED_A)
A16: A | B16: RV1 | C16: 50k trim | D16: 1 | E16: 1 | F16: SENSE | G16: U3.E, J1.4, C1.1 | H16: Wire (or label SENSE)
A17: A | B17: RV1 | C17: 50k trim | D17: 2 | E17: wiper | F17: GND | G17: Power net — 27 pins share it (see Nets tab) | H17: power:GND symbol
... A35: A | B35: C3 | C35: 100nF | D35: 2 | E35: ~ | F35: GND | G35: Power net — 27 pins share it (see Nets tab) | H35: power:GND symbol
A36: B · 1.65 V reference
A37: B | B37: R6 | C37: 10k | D37: 1 | E37: ~ | F37: +3V3 | G37: Power net — 13 pins share it (see Nets tab) | H37: power:+3V3 symbol
A38: B | B38: R6 | C38: 10k | D38: 2 | E38: ~ | F38: REF_DIV | G38: R7.1, C4.1, U1.5 | H38: Wire (or label REF_DIV)
A39: B | B39: R7 | C39: 10k | D39: 1 | E39: ~ | F39: REF_DIV | G39: R6.2, C4.1, U1.5 | H39: Wire (or label REF_DIV)
A40: B | B40: R7 | C40: 10k | D40: 2 | E40: ~ | F40: GND | G40: Power net — 27 pins share it (see Nets tab) | H40: power:GND symbol
A41: B | B41: C4 | C41: 10µF | D41: 1 | E41: + | F41: REF_DIV | G41: R6.2, R7.1, U1.5 | H41: Wire (or label REF_DIV)
A42: B | B42: C4 | C42: 10µF | D42: 2 | E42: − | F42: GND | G42: Power net — 27 pins share it (see Nets tab) | H42: power:GND symbol
A43: B | B43: U1 | C43: MCP6002 · unit B | D43: 5 | E43: + | F43: REF_DIV | G43: R6.2, R7.1, C4.1 | H43: Wire (or label REF_DIV)
A44: B | B44: U1 | C44: MCP6002 · unit B | D44: 6 | E44: − | F44: VREF | G44: R2.2, R3.2, U1.7 | H44: Label VREF (used in 2 blocks)
A45: B | B45: U1 | C45: MCP6002 · unit B | D45: 7 | E45: OUT | F45: VREF | G45: R2.2, R3.2, U1.6 | H45: Label VREF (used in 2 blocks)
A46: B | B46: U1 | C46: MCP6002 · unit C (power) | D46: 8 | E46: V+ | F46: +3V3 | G46: Power net — 13 pins share it (see Nets tab) | H46: power:+3V3 symbol
A47: B | B47: U1 | C47: MCP6002 · unit C (power) | D47: 4 | E47: V− | F47: GND | G47: Power net — 27 pins share it (see Nets tab) | H47: power:GND symbol
A48: B | B48: C5 | C48: 100nF | D48: 1 | E48: ~ | F48: +3V3 | G48: Power net — 13 pins share it (see Nets tab) | H48: power:+3V3 symbol
A49: B | B49: C5 | C49: 100nF | D49: 2 | E49: ~ | F49: GND | G49: Power net — 27 pins share it (see Nets tab) | H49: power:GND symbol
A50: C · Heater power switch
A51: C | B51: J4 | C51: XT30 | D51: 1 | E51: + | F51: +14V8 | G51: Power net — 6 pins share it (see Nets tab) | H51: power:VCC symbol, change Value to +14V8
A52: C | B52: J4 | C52: XT30 | D52: 2 | E52: − | F52: GNDPWR | G52: Power net — 5 pins share it (see Nets tab) | H52: power:GNDPWR symbol
A53: C | B53: C6 | C53: 10µF 50V | D53: 1 | E53: + | F53: +14V8 | G53: Power net — 6 pins share it (see Nets tab) | H53: power:VCC symbol, change Value to +14V8
A54: C | B54: C6 | C54: 10µF 50V | D54: 2 | E54: − | F54: GNDPWR | G54: Power net — 5 pins share it (see Nets tab) | H54: power:GNDPWR symbol
A55: C | B55: J5 | C55: Terminal 1×2 (KF2EDG) | D55: 1 | E55: Pin_1 | F55: +14V8 | G55: Power net — 6 pins share it (see Nets tab) | H55: power:VCC symbol, change Value to +14V8
A56: C | B56: J5 | C56: Terminal 1×2 (KF2EDG) | D56: 2 | E56: Pin_2 | F56: HEATER_LO | G56: R8.2, R9.2, R10.2, Q1.2 | H56: Label HEATER_LO
A57: C | B57: R8 | C57: 150Ω 5W | D57: 1 | E57: ~ | F57: +14V8 | G57: Power net — 6 pins share it (see Nets tab) | H57: power:VCC symbol, change Value to +14V8
A58: C | B58: R8 | C58: 150Ω 5W | D58: 2 | E58: ~ | F58: HEATER_LO | G58: J5.2, R9.2, R10.2, Q1.2 | H58: Label HEATER_LO
...

Sheet Nets
A1: Net | B1: Type | C1: How to draw it | D1: Pins on this net | E1: Pins expected | F1: Pins found in Wiring tab | G1: Check
A2: +5V | B2: Power | C2: power:+5V symbol | D2: R1.1, U2.8, C7.1, J2.1 | E2: 4 | F2: =COUNTIF(Wiring!$F$5:$F$125,A2) -> 4 | G2: =IF(F2=E2,"OK","CHECK") -> OK
A3: +3V3 | B3: Power | C3: power:+3V3 symbol | D3: U3.C, J1.3, R6.1, U1.8, C5.1, R14.1, R13.1, RV2.1, J2.2, C8.1, J7.1, J8.1, J9.1 | E3: 13 | F3: =COUNTIF(Wiring!$F$5:$F$125,A3) -> 13 | G3: =IF(F3=E3,"OK","CHECK") -> OK
A4: +14V8 | B4: Power | C4: power:VCC symbol, change Value to +14V8 | D4: J4.1, C6.1, J5.1, R8.1, R9.1, R10.1 | E4: 6 | F4: =COUNTIF(Wiring!$F$5:$F$125,A4) -> 6 | G4: =IF(F4=E4,"OK","CHECK") -> OK
A5: GND | B5: Ground | C5: power:GND symbol | D5: U3.K, J1.2, RV1.2, RV1.3, C3.2, R7.2, C4.2, U1.4, C5.2, NT1.2, J6.2, J6.4, TH1.2, C10.2, TH2.2, C11.2, RV2.3, U2.5, U2.6, U2.4, C7.2, J2.3, C8.2, J7.2, J8.2, J8.5, J9.2 | E5: 27 | F5: =COUNTIF(Wiring!$F$5:$F$125,A5) -> 27 | G5: =IF(F5=E5,"OK","CHECK") -> OK
A6: GNDPWR | B6: Ground | C6: power:GNDPWR symbol | D6: J4.2, C6.2, Q1.3, R12.2, NT1.1 | E6: 5 | F6: =COUNTIF(Wiring!$F$5:$F$125,A6) -> 5 | G6: =IF(F6=E6,"OK","CHECK") -> OK
A7: LED_A | B7: Analog | C7: Wire (or label LED_A) | D7: U3.A, J1.1, R1.2 | E7: 3 | F7: =COUNTIF(Wiring!$F$5:$F$125,A7) -> 3 | G7: =IF(F7=E7,"OK","CHECK") -> OK
A8: SENSE | B8: Analog | C8: Wire (or label SENSE) | D8: U3.E, J1.4, RV1.1, C1.1 | E8: 4 | F8: =COUNTIF(Wiring!$F$5:$F$125,A8) -> 4 | G8: =IF(F8=E8,"OK","CHECK") -> OK
A9: HP_IN | B9: Analog | C9: Wire (or label HP_IN) | D9: C1.2, R2.1, U1.3 | E9: 3 | F9: =COUNTIF(Wiring!$F$5:$F$125,A9) -> 3 | G9: =IF(F9=E9,"OK","CHECK") -> OK
A10: FB | B10: Analog | C10: Wire (or label FB) | D10: U1.2, R3.1, R4.1, C2.1 | E10: 4 | F10: =COUNTIF(Wiring!$F$5:$F$125,A10) -> 4 | G10: =IF(F10=E10,"OK","CHECK") -> OK
A11: AMP_OUT | B11: Analog | C11: Wire (or label AMP_OUT) | D11: U1.1, R4.2, C2.2, R5.1 | E11: 4 | F11: =COUNTIF(Wiring!$F$5:$F$125,A11) -> 4 | G11: =IF(F11=E11,"OK","CHECK") -> OK
A12: HB_ADC | B12: Analog | C12: Label HB_ADC | D12: R5.2, C3.1, J3.1 | E12: 3 | F12: =COUNTIF(Wiring!$F$5:$F$125,A12) -> 3 | G12: =IF(F12=E12,"OK","CHECK") -> OK
A13: REF_DIV | B13: Analog | C13: Wire (or label REF_DIV) | D13: R6.2, R7.1, C4.1, U1.5 | E13: 4 | F13: =COUNTIF(Wiring!$F$5:$F$125,A13) -> 4 | G13: =IF(F13=E13,"OK","CHECK") -> OK
... A22: SDA | B22: Digital I²C | C22: Label SDA | D22: J3.5, J7.4, J8.4, J9.4 | E22: 4 | F22: =COUNTIF(Wiring!$F$5:$F$125,A22) -> 4 | G22: =IF(F22=E22,"OK","CHECK") -> OK
A23: (no connect) | C23: No-Connect flag | D23: U2.7

Sheet Connectors
A1: Plugs and cables — what each wire goes to off the board
A3: Plug | B3: Type | C3: Pin | D3: Net | E3: Wire goes to (other end) | F3: Suggested wire colour
A4: J1 · Sensor cable | B4: JST-XH 4-pin | C4: 1 | D4: LED_A | E4: TCRT5000 pin A (LED anode) | F4: Green
C5: 2 | D5: GND | E5: TCRT5000 pin K (LED cathode) | F5: Black
C6: 3 | D6: +3V3 | E6: TCRT5000 pin C (collector) | F6: Red
C7: 4 | D7: SENSE | E7: TCRT5000 pin E (emitter) | F7: Yellow
A8: J2 · Flight computer power | B8: JST-XH 3-pin | C8: 1 | D8: +5V | E8: Flight computer 5V | F8: Red
C9: 2 | D9: +3V3 | E9: Flight computer 3V3 | F9: Orange
C10: 3 | D10: GND | E10: Flight computer GND | F10: Black
A11: J3 · Flight computer signals | B11: JST-XH 5-pin | C11: 1 | D11: HB_ADC | E11: PB0 (ADC) | F11: Yellow
C12: 2 | D12: NTC1_ADC | E12: PB1 (ADC) | F12: White
C13: 3 | D13: PWM | E13: PC6 (PWM) | F13: Green
C14: 4 | D14: SCL | E14: PD12 (I²C4 SCL) | F14: Blue
C15: 5 | D15: SDA | E15: PD13 (I²C4 SDA) | F15: Purple
A16: J4 · 14.8 V in | B16: XT30 | C16: 1 | D16: +14V8 | E16: Port X8 + (14.8 V) | F16: Red, 20 AWG
C17: 2 | D17: GNDPWR | E17: Port X8 − | F17: Black, 20 AWG
A18: J5 · Heater | B18: KF2EDG 2-pin | C18: 1 | D18: +14V8 | E18: Heater bank: R8, R9, R10 joined at one end | F18: Red
C19: 2 | D19: HEATER_LO | E19: Heater bank: R8, R9, R10 joined at other end | F19: Black
A20: J6 · Thermistors | B20: JST-XH 4-pin | C20: 1 | D20: NTC1_ADC | E20: TH1 leg 1 (taped to heater) | F20: White
C21: 2 | D21: GND | E21: TH1 leg 2 | F21: Black
C22: 3 | D22: NTC2 | E22: TH2 leg 1 (taped to heater) | F22: Brown
C23: 4 | D23: GND | E23: TH2 leg 2 | F23: Black
A24: J7 · SHT21 module | B24: JST-XH 4-pin | C24: 1 | D24: +3V3 | E24: Module VIN | F24: Red
C25: 2 | D25: GND | E25: Module GND | F25: Black
C26: 3 | D26: SCL | E26: Module SCL | F26: Blue
C27: 4 | D27: SDA | E27: Module SDA | F27: Purple
A28: J8 · BMP280 module | B28: JST-XH 5-pin | C28: 1 | D28: +3V3 | E28: Module VCC | F28: Red
C29: 2 | D29: GND | E29: Module GND | F29: Black
C30: 3 | D30: SCL | E30: Module SCL | F30: Blue
C31: 4 | D31: SDA | E31: Module SDA | F31: Purple
C32: 5 | D32: GND | E32: Module SDO (sets address 0x76) | F32: Black
A33: J9 · MAX30100 module | B33: JST-XH 4-pin | C33: 1 | D33: +3V3 | E33: Module VIN | F33: Red
C34: 2 | D34: GND | E34: Module GND | F34: Black
C35: 3 | D35: SCL | E35: Module SCL | F35: Blue
C36: 4 | D36: SDA | E36: Module SDA | F36: Purple
A38: Note: the MAX30100 board's I²C pull-ups go to 1.8 V on many cheap modules. If the STM32 can't read it, that's why — it's the backup sensor anyway.
